Workbook

Sheet Data
A1: IdNum | B1: WorkHrs | C1: Occup_n | D1: Age | E1: Educ_Yrs | F1: Sex | G1: MemUnion | H1: WrkYears | I1: EmpYears | J1: NumPromo | K1: FutPromo | L1: SexPromo | M1: AwareI4 | N1: lessThan3 | O1: probability_B | P1: Seminar | Q1: Cost/Seminar | R1: Salary
A2: 234 | B2: 55 | C2: 7.Laborer | D2: 21 | E2: 12 | F2: Female | G2: Yes Union | H2: 4 | I2: 2 | J2: 0 | K2: 1.V Likely | L2: 3.No Effect | M2: No | N2: 1 | O2: 0.89676023 | P2: 0.03 | Q2: 1 | R2: 0.05
A3: 101 | B3: 50 | C3: 5.Service | D3: 25 | E3: 14 | F3: Male | G3: Yes Union | H3: 8 | I3: 3 | J3: 0 | K3: 1.V Likely | L3: 3.No Effect | M3: Yes | N3: 0 | O3: 0.86692112 | P3: 0.02 | Q3: 1.3 | R3: 0.07
A4: 126 | B4: 40 | C4: 5.Service | D4: 26 | E4: 12 | F4: Male | G4: No Union | H4: 8 | I4: 1 | J4: 0 | K4: 1.V Likely | L4: 3.No Effect | M4: No | N4: 1 | O4: 0.86346265 | P4: 0.02 | Q4: 1.3 | R4: 0.07
A5: 56 | B5: 40 | C5: 1.Manag | D5: 25 | E5: 16 | F5: Male | G5: No Union | H5: 2 | I5: 2 | J5: 0 | K5: 1.V Likely | L5: 1.Better | M5: Yes | N5: 1 | O5: 0.82054187 | P5: 0.02 | Q5: 0.6 | R5: 0.07
A6: 337 | B6: 40 | C6: 6.Prod'n | D6: 32 | E6: 14 | F6: Male | G6: Yes Union | H6: 16 | I6: 1 | J6: 0 | K6: 1.V Likely | L6: 3.No Effect | M6: Yes | N6: 1 | O6: 0.79054317 | P6: 0.03 | Q6: 1.2 | R6: 0.07
A7: 376 | B7: 50 | C7: 2.Prof'nal | D7: 27 | E7: 17 | F7: Female | G7: No Union | H7: 7 | I7: 1 | J7: 0 | K7: 1.V Likely | L7: 2.Worse | M7: Yes | N7: 1 | O7: 0.78610237 | P7: 0.01 | Q7: 0.9 | R7: 0.05
A8: 354 | B8: 56 | C8: 2.Prof'nal | D8: 24 | E8: 16 | F8: Female | G8: No Union | H8: 9 | I8: 2 | J8: 0 | K8: 1.V Likely | L8: 1.Better | M8: Yes | N8: 1 | O8: 0.77794421 | P8: 0.01 | Q8: 0.9 | R8: 0.05
A9: 111 | B9: 60 | C9: 3.Tech/Sales | D9: 23 | E9: 16 | F9: Male | G9: No Union | H9: 6 | I9: 1 | J9: 1 | K9: 1.V Likely | L9: 3.No Effect | M9: No | N9: 1 | O9: 0.77162652 | P9: 0.01 | Q9: 1.3 | R9: 0.07
A10: 145 | B10: 42 | C10: 3.Tech/Sales | D10: 36 | E10: 18 | F10: Female | G10: No Union | H10: 19 | I10: 1 | J10: 0 | K10: 1.V Likely | L10: 3.No Effect | M10: Yes | N10: 1 | O10: 0.74701458 | P10: 0.01 | Q10: 1.3 | R10: 0.05
A11: 437 | B11: 42 | C11: 3.Tech/Sales | D11: 36 | E11: 18 | F11: Female | G11: No Union | H11: 19 | I11: 1 | J11: 0 | K11: 1.V Likely | L11: 3.No Effect | M11: Yes | N11: 1 | O11: 0.74701458 | P11: 0.01 | Q11: 1.3 | R11: 0.05
A12: 569 | B12: 42 | C12: 3.Tech/Sales | D12: 36 | E12: 18 | F12: Female | G12: No Union | H12: 19 | I12: 1 | J12: 0 | K12: 1.V Likely | L12: 3.No Effect | M12: Yes | N12: 1 | O12: 0.74701458 | P12: 0.01 | Q12: 1.3 | R12: 0.05
A13: 612 | B13: 42 | C13: 3.Tech/Sales | D13: 36 | E13: 18 | F13: Female | G13: No Union | H13: 19 | I13: 1 | J13: 0 | K13: 1.V Likely | L13: 3.No Effect | M13: Yes | N13: 1 | O13: 0.74701458 | P13: 0.01 | Q13: 1.3 | R13: 0.05
... A21: 668 | B21: 38 | C21: 7.Laborer | D21: 26 | E21: 15 | F21: Male | G21: No Union | H21: 9 | I21: 0.5 | J21: 1 | K21: 1.V Likely | L21: 3.No Effect | M21: No | N21: 1 | O21: 0.73139701 | P21: 0.03 | Q21: 1 | R21: 0.07
A29: IdNum | B29: Occup_n | C29: Sex | D29: probability_B
A30: 234 | B30: Laborer | C30: Female | D30: 0.89676023
A31: 101 | B31: Service | C31: Male | D31: 0.86692112
A32: 126 | B32: Service | C32: Male | D32: 0.86346265
A33: 56 | B33: Management | C33: Male | D33: 0.82054187
A34: 337 | B34: Production | C34: Male | D34: 0.79054317
A35: 376 | B35: Professional | C35: Female | D35: 0.78610237
A36: 354 | B36: Professional | C36: Female | D36: 0.77794421
A37: 111 | B37: Tech/Sales | C37: Male | D37: 0.77162652
A38: 145 | B38: Tech/Sales | C38: Female | D38: 0.74701458
A39: 437 | B39: Tech/Sales | C39: Female | D39: 0.74701458
A40: 569 | B40: Tech/Sales | C40: Female | D40: 0.74701458
A41: 612 | B41: Tech/Sales | C41: Female | D41: 0.74701458
... A49: 668 | B49: Laborer | C49: Male | D49: 0.73139701

Sheet 10% Strategy
B2: 10% PROBABILITY REDUCTION STRATEGY
B4: EMPLOYEE EFFECT
B5: ID Number | C5: Salary Increase Effect (per $1,000) | D5: Seminar Effect (per hour) | E5: Cost per Hour (in $1000) | F5: Estimated cost of person per hour in seminar
B6: 234 | C6: =Data!R2 -> 0.05 | D6: =Data!P2 -> 0.03 | E6: =Data!Q2 -> 1 | F6: =D6*E6 -> 0.03
B7: 101 | C7: =Data!R3 -> 0.07 | D7: =Data!P3 -> 0.02 | E7: =Data!Q3 -> 1.3 | F7: =D7*E7 -> 0.026
B8: 126 | C8: =Data!R4 -> 0.07 | D8: =Data!P4 -> 0.02 | E8: =Data!Q4 -> 1.3 | F8: =D8*E8 -> 0.026
B9: 56 | C9: =Data!R5 -> 0.07 | D9: =Data!P5 -> 0.02 | E9: =Data!Q5 -> 0.6 | F9: =D9*E9 -> 0.012
B10: 337 | C10: =Data!R6 -> 0.07 | D10: =Data!P6 -> 0.03 | E10: =Data!Q6 -> 1.2 | F10: =D10*E10 -> 0.036
B11: 376 | C11: =Data!R7 -> 0.05 | D11: =Data!P7 -> 0.01 | E11: =Data!Q7 -> 0.9 | F11: =D11*E11 -> 0.009
B12: 354 | C12: =Data!R8 -> 0.05 | D12: =Data!P8 -> 0.01 | E12: =Data!Q8 -> 0.9 | F12: =D12*E12 -> 0.009
B13: 111 | C13: =Data!R9 -> 0.07 | D13: =Data!P9 -> 0.01 | E13: =Data!Q9 -> 1.3 | F13: =D13*E13 -> 0.013
B14: 145 | C14: =Data!R10 -> 0.05 | D14: =Data!P10 -> 0.01 | E14: =Data!Q10 -> 1.3 | F14: =D14*E14 -> 0.013
B15: 437 | C15: =Data!R11 -> 0.05 | D15: =Data!P11 -> 0.01 | E15: =Data!Q11 -> 1.3 | F15: =D15*E15 -> 0.013
B16: 569 | C16: =Data!R12 -> 0.05 | D16: =Data!P12 -> 0.01 | E16: =Data!Q12 -> 1.3 | F16: =D16*E16 -> 0.013
B17: 612 | C17: =Data!R13 -> 0.05 | D17: =Data!P13 -> 0.01 | E17: =Data!Q13 -> 1.3 | F17: =D17*E17 -> 0.013
... B25: 668 | C25: =Data!R21 -> 0.07 | D25: =Data!P21 -> 0.03 | E25: =Data!Q21 -> 1 | F25: =D25*E25 -> 0.03
B28: DECISION VARIABLES
B29: ID Number | C29: Salary Increase (in $1,000) | D29: Seminar Hours | E29: Estimated cost of person per hour in seminar
B30: 234 | C30: 0.2 | D30: 3 | E30: =D30*E6*D6 -> 0.09
B31: 101 | C31: 1.4285714 | D31: 0 | E31: =D31*E7*D7 -> 0
B32: 126 | C32: 1.4285714 | D32: 0 | E32: =D32*E8*D8 -> 0
B33: 56 | C33: 1.4285714 | D33: 0 | E33: =D33*E9*D9 -> 0
B34: 337 | C34: 1.4285714 | D34: 0 | E34: =D34*E10*D10 -> 0
B35: 376 | C35: 2 | D35: 0 | E35: =D35*E11*D11 -> 0
B36: 354 | C36: 2 | D36: 0 | E36: =D36*E12*D12 -> 0
B37: 111 | C37: 1.4285714 | D37: 0 | E37: =D37*E13*D13 -> 0
B38: 145 | C38: 2 | D38: 0 | E38: =D38*E14*D14 -> 0
B39: 437 | C39: 2 | D39: 0 | E39: =D39*E15*D15 -> 0
B40: 569 | C40: 2 | D40: 0 | E40: =D40*E16*D16 -> 0
B41: 612 | C41: 2 | D41: 0 | E41: =D41*E17*D17 -> 0
... B49: 668 | C49: 0.14285714 | D49: 3 | E49: =D49*E25*D25 -> 0.09
B53: OBJECTIVE | C53: Minimize cost
B54: Total Cost (in $1,000) | C54: =SUM(C30:C49)+SUM(E30:E49) -> 27.278571
B57: CONSTRAINTS
B58: Constraints: Budget | E58: Budget | F58: Slack
B59: Total Seminar Hours | C59: =SUM(D30:D49) -> 15 | D59: <= | E59: 15 | F59: =E59-C59 -> 0 | G59: Binding
B60: Total Salary Increase | C60: =SUM(C30:C49) -> 26.828571 | D60: <= | E60: 50 | F60: =E60-C60 -> 23.171429 | G60: Non-binding
B62: Individual Constraints: Department and Sex
B63: ID Number | C63: Salary Effect | D63: Seminar Effect | E63: Total Reduction | G63: Target Reduction | H63: Probability | I63: Probability after reduction
B64: 234 | C64: =C30*C6 -> 0.01 | D64: =D30*D6 -> 0.09 | E64: =SUM(C64:D64) -> 0.1 | F64: = | G64: 0.1 | H64: {=Data!O2:O21} -> 0.89676023 | I64: =H64-G64 -> 0.79676023
...

Sheet 40% Strategy 
B2: 40% PROBABILITY REDUCTION STRATEGY
B4: EMPLOYEE EFFECT
B5: ID Number | C5: Salary Increase Effect (per $1,000) | D5: Seminar Effect (per hour) | E5: Cost per Hour (in $1000) | F5: Estimated cost of person per hour in seminar
B6: 234 | C6: =Data!R2 -> 0.05 | D6: =Data!P2 -> 0.03 | E6: =Data!Q2 -> 1 | F6: =D6*E6 -> 0.03
B7: 101 | C7: =Data!R3 -> 0.07 | D7: =Data!P3 -> 0.02 | E7: =Data!Q3 -> 1.3 | F7: =D7*E7 -> 0.026
B8: 126 | C8: =Data!R4 -> 0.07 | D8: =Data!P4 -> 0.02 | E8: =Data!Q4 -> 1.3 | F8: =D8*E8 -> 0.026
B9: 56 | C9: =Data!R5 -> 0.07 | D9: =Data!P5 -> 0.02 | E9: =Data!Q5 -> 0.6 | F9: =D9*E9 -> 0.012
B10: 337 | C10: =Data!R6 -> 0.07 | D10: =Data!P6 -> 0.03 | E10: =Data!Q6 -> 1.2 | F10: =D10*E10 -> 0.036
B11: 376 | C11: =Data!R7 -> 0.05 | D11: =Data!P7 -> 0.01 | E11: =Data!Q7 -> 0.9 | F11: =D11*E11 -> 0.009
B12: 354 | C12: =Data!R8 -> 0.05 | D12: =Data!P8 -> 0.01 | E12: =Data!Q8 -> 0.9 | F12: =D12*E12 -> 0.009
B13: 111 | C13: =Data!R9 -> 0.07 | D13: =Data!P9 -> 0.01 | E13: =Data!Q9 -> 1.3 | F13: =D13*E13 -> 0.013
B14: 145 | C14: =Data!R10 -> 0.05 | D14: =Data!P10 -> 0.01 | E14: =Data!Q10 -> 1.3 | F14: =D14*E14 -> 0.013
B15: 437 | C15: =Data!R11 -> 0.05 | D15: =Data!P11 -> 0.01 | E15: =Data!Q11 -> 1.3 | F15: =D15*E15 -> 0.013
B16: 569 | C16: =Data!R12 -> 0.05 | D16: =Data!P12 -> 0.01 | E16: =Data!Q12 -> 1.3 | F16: =D16*E16 -> 0.013
B17: 612 | C17: =Data!R13 -> 0.05 | D17: =Data!P13 -> 0.01 | E17: =Data!Q13 -> 1.3 | F17: =D17*E17 -> 0.013
... B25: 668 | C25: =Data!R21 -> 0.07 | D25: =Data!P21 -> 0.03 | E25: =Data!Q21 -> 1 | F25: =D25*E25 -> 0.03
B28: DECISION VARIABLES
B29: ID Number | C29: Salary Increase (in $1,000) | D29: Seminar Hours | E29: Estimated cost of person per hour in seminar
B30: 234 | C30: 0 | D30: 0 | E30: =D30*E6*D6 -> 0
B31: 101 | C31: 0 | D31: 0 | E31: =D31*E7*D7 -> 0
B32: 126 | C32: 0 | D32: 0 | E32: =D32*E8*D8 -> 0
B33: 56 | C33: 0 | D33: 0 | E33: =D33*E9*D9 -> 0
B34: 337 | C34: 0 | D34: 0 | E34: =D34*E10*D10 -> 0
B35: 376 | C35: 8 | D35: 0 | E35: =D35*E11*D11 -> 0
B36: 354 | C36: 8 | D36: 0 | E36: =D36*E12*D12 -> 0
B37: 111 | C37: 0 | D37: 0 | E37: =D37*E13*D13 -> 0
B38: 145 | C38: 8 | D38: 0 | E38: =D38*E14*D14 -> 0
B39: 437 | C39: 8 | D39: 0 | E39: =D39*E15*D15 -> 0
B40: 569 | C40: 8 | D40: 0 | E40: =D40*E16*D16 -> 0
B41: 612 | C41: 8 | D41: 0 | E41: =D41*E17*D17 -> 0
... B49: 668 | C49: 0 | D49: 13.333333 | E49: =D49*E25*D25 -> 0.4
B53: OBJECTIVE | C53: Minimize cost
B54: Total Cost (in $1,000) | C54: =SUM(C30:C49)+SUM(E30:E49) -> 50.45
B57: CONSTRAINTS
B58: Global Constraints: Budget | E58: Budget | F58: Slack
B59: Total Seminar Hours | C59: =SUM(D30:D49) -> 15 | D59: <= | E59: 15 | F59: =E59-C59 -> 0 | G59: Binding
B60: Total Salary Increase | C60: =SUM(C30:C49) -> 50 | D60: <= | E60: 50 | F60: =E60-C60 -> 0 | G60: Binding
B62: Individual Constraints: Department and Sex
B63: ID Number | C63: Salary Effect | D63: Seminar Effect | E63: Total Reduction | G63: Target Reduction | H63: Probability | I63: Probability after reduction
B64: 234 | C64: =C30*C6 -> 0 | D64: =D30*D6 -> 0 | E64: =SUM(C64:D64) -> 0 | F64: = | G64: 0.4 | H64: {=Data!O2:O21} -> 0.89676023 | I64: =H64-G64 -> 0.49676023
...
